Workbook

Sheet Valuation
B1: FY 24 | C1: FY25E | D1: FY26E | E1: FY27E | F1: FY28E | G1: FY29E | H1: FY30E | I1: FY31E | J1: FY32E | L1: Tax Rate | M1: 0.25
B2: 0 | C2: 1 | D2: 2 | E2: 3 | F2: 4 | G2: 5 | H2: 6 | I2: 7 | J2: 8 | L2: WACC | M2: =WACC!F7 -> 0.090262332
A3: EBIT * (1-t) | B3: ='Financial Statements'!E151*(1-0.25) -> 459066 | C3: ='Financial Statements'!F151*(1-0.25) -> 609358.95 | D3: ='Financial Statements'!G151*(1-0.25) -> 665961.27 | E3: ='Financial Statements'!H151*(1-0.25) -> 721866.45 | F3: ='Financial Statements'!I151*(1-0.25) -> 775340.78 | G3: ='Financial Statements'!J151*(1-0.25) -> 825945.58 | H3: ='Financial Statements'!K151*(1-0.25) -> 879129.22 | I3: ='Financial Statements'!L151*(1-0.25) -> 927075.27 | J3: ='Financial Statements'!M151*(1-0.25) -> 976690.53 | L3: Long Term Growth Rate | M3: ='Revenue Prediction'!M3 -> 0.053518047
A4: Add: Depreciation
A5: Depreciation of Tangible Assets | B5: ='Financial Statements'!E92 -> 93420 | C5: ='Financial Statements'!F92 -> 93420 | D5: ='Financial Statements'!G92 -> 119312.15 | E5: ='Financial Statements'!H92 -> 143381.29 | F5: ='Financial Statements'!I92 -> 166019.29 | G5: ='Financial Statements'!J92 -> 187382.84 | H5: ='Financial Statements'!K92 -> 207554.97 | I5: ='Financial Statements'!L92 -> 227035.01 | J5: ='Financial Statements'!M92 -> 245573.16
A6: Depreciation of Intangible Assets | B6: ='Financial Statements'!E94 -> 41154 | C6: ='Financial Statements'!F94 -> 41154 | D6: ='Financial Statements'!G94 -> 44067.39 | E6: ='Financial Statements'!H94 -> 47259.352 | F6: ='Financial Statements'!I94 -> 50723.705 | G6: ='Financial Statements'!J94 -> 54445.01 | H6: ='Financial Statements'!K94 -> 58405.604 | I6: ='Financial Statements'!L94 -> 62617.249 | J6: ='Financial Statements'!M94 -> 67049.613
A7: Depreciation of Rights-of-Use Assets | B7: ='Financial Statements'!E96 -> 75921 | C7: ='Financial Statements'!F96 -> 75921 | D7: ='Financial Statements'!G96 -> 60132.511 | E7: ='Financial Statements'!H96 -> 47627.388 | F7: ='Financial Statements'!I96 -> 37722.823 | G7: ='Financial Statements'!J96 -> 29878.006 | H7: ='Financial Statements'!K96 -> 23664.593 | I7: ='Financial Statements'!L96 -> 18743.317 | J7: ='Financial Statements'!M96 -> 14845.468
A8: Amortization of R&D Asset | B8: ='CapEx Readjustments'!E13 -> 0 | C8: ='CapEx Readjustments'!F13 -> 21676.312 | D8: ='CapEx Readjustments'!G13 -> 27021.983 | E8: ='CapEx Readjustments'!H13 -> 32031.155 | F8: ='CapEx Readjustments'!I13 -> 36775.637 | G8: ='CapEx Readjustments'!J13 -> 41278.66 | H8: ='CapEx Readjustments'!K13 -> 45549.897 | I8: ='CapEx Readjustments'!L13 -> 49692.85 | J8: ='CapEx Readjustments'!M13 -> 53647.065
A9: Total Depreciation | B9: =SUM(B5:B8) -> 210495 | C9: =SUM(C5:C8) -> 232171.31 | D9: =SUM(D5:D8) -> 250534.03 | E9: =SUM(E5:E8) -> 270299.18 | F9: =SUM(F5:F8) -> 291241.45 | G9: =SUM(G5:G8) -> 312984.51 | H9: =SUM(H5:H8) -> 335175.07 | I9: =SUM(I5:I8) -> 358088.43 | J9: =SUM(J5:J8) -> 381115.31
A10: Less: Change in Non-Cash WC | B10: =-'Financial Statements'!E116 -> -41231 | C10: =-'Financial Statements'!F116 -> -80889.163 | D10: =-'Financial Statements'!G116 -> -29108.143 | E10: =-'Financial Statements'!H116 -> -28749.638 | F10: =-'Financial Statements'!I116 -> -27499.553 | G10: =-'Financial Statements'!J116 -> -26023.877 | H10: =-'Financial Statements'!K116 -> -27350.064 | I10: =-'Financial Statements'!L116 -> -24656.6 | J10: =-'Financial Statements'!M116 -> -25514.998
A11: Less: Capital Expenditure
A12: Puchase of Property, Plant & Equipment | B12: ='Financial Statements'!E119 -> -190919 | C12: ='Financial Statements'!F119 -> -198838.91 | D12: ='Financial Statements'!G119 -> -217308.72 | E12: ='Financial Statements'!H119 -> -235551.05 | F12: ='Financial Statements'!I119 -> -253000.17 | G12: ='Financial Statements'!J119 -> -269512.94 | H12: ='Financial Statements'!K119 -> -286867.2 | I12: ='Financial Statements'!L119 -> -302512.4 | J12: ='Financial Statements'!M119 -> -318702.28
A13: Business Combinations | B13: ='Financial Statements'!E124 -> -265288 | C13: ='Financial Statements'!F124 -> -374283.12 | D13: ='Financial Statements'!G124 -> -409049.64 | E13: ='Financial Statements'!H124 -> -443387.97 | F13: ='Financial Statements'!I124 -> -476233.2 | G13: ='Financial Statements'!J124 -> -507315.9 | H13: ='Financial Statements'!K124 -> -539982.59 | I13: ='Financial Statements'!L124 -> -569432.23 | J13: ='Financial Statements'!M124 -> -599907.13
A14: Investment in R&D Asset | B14: ='Financial Statements'!E127 -> 0 | C14: ='Financial Statements'!F127 -> -43058.993 | D14: ='Financial Statements'!G127 -> -47058.67 | E14: ='Financial Statements'!H127 -> -51009.085 | F14: ='Financial Statements'!I127 -> -54787.73 | G14: ='Financial Statements'!J127 -> -58363.605 | H14: ='Financial Statements'!K127 -> -62121.709 | I14: ='Financial Statements'!L127 -> -65509.71 | J14: ='Financial Statements'!M127 -> -69015.662
A15: Total Capital Expenditure | B15: =SUM(B12:B14) -> -456207 | C15: =SUM(C12:C14) -> -616181.02 | D15: =SUM(D12:D14) -> -673417.03 | E15: =SUM(E12:E14) -> -729948.1 | F15: =SUM(F12:F14) -> -784021.1 | G15: =SUM(G12:G14) -> -835192.45 | H15: =SUM(H12:H14) -> -888971.51 | I15: =SUM(I12:I14) -> -937454.34 | J15: =SUM(J12:J14) -> -987625.07
A16: FCFF | B16: =B3+B9+B10+B15 -> 172123 | C16: =C3+C9+C10+C15 -> 144460.07 | D16: =D3+D9+D10+D15 -> 213970.13 | E16: =E3+E9+E10+E15 -> 233467.89 | F16: =F3+F9+F10+F15 -> 255061.57 | G16: =G3+G9+G10+G15 -> 277713.76 | H16: =H3+H9+H10+H15 -> 297982.72 | I16: =I3+I9+I10+I15 -> 323052.76 | J16: =J3+J9+J10+J15 -> 344665.78 | K16: =J16*(1+M3) -> 363111.62
A17: Terminal Value | J17: =K16/(M2-M3) -> 9882125
A18: PV of FCFF | C18: =C16/((1+$M$2)^C2) -> 132500.29 | D18: =D16/((1+$M$2)^D2) -> 180007.72 | E18: =E16/((1+$M$2)^E2) -> 180149.94 | F18: =F16/((1+$M$2)^F2) -> 180518.2 | G18: =G16/((1+$M$2)^G2) -> 180277.85 | H18: =H16/((1+$M$2)^H2) -> 177421 | I18: =I16/((1+$M$2)^I2) -> 176423.49 | J18: =SUM(J16:J17)/((1+$M$2)^J2) -> 5122610.2
A20: Value of Operating Assets | B20: =B16+SUM(C18:J18) -> 6502031.7 | J20: All figures in millions

Sheet Revenue Prediction
B1: 2021 | C1: 2022 | D1: 2023 | E1: 2024 | F1: 2025 | G1: 2026 | H1: 2027 | I1: 2028 | J1: 2029 | K1: 2030 | L1: 2031 | M1: 2032
A2: Puig Total Revenue | B2: 2585012 | C2: 3619603 | D2: 4304067 | E2: 4789779 | F2: =SUM(F6:F8) -> 5200171.5 | G2: =SUM(G6:G8) -> 5683206.6 | H2: =SUM(H6:H8) -> 6160292.5 | I2: =SUM(I6:I8) -> 6616633.9 | J2: =SUM(J6:J8) -> 7048487.1 | K2: =SUM(K6:K8) -> 7502347.7 | L2: =SUM(L6:L8) -> 7911511.7 | M2: =SUM(M6:M8) -> 8334920.4
A3: Revenue Growth % | C3: =C2/B2-1 -> 0.40022677 | D3: =D2/C2-1 -> 0.18909919 | E3: =E2/D2-1 -> 0.11284954 | F3: =F2/E2-1 -> 0.085680893 | G3: =G2/F2-1 -> 0.0928883 | H3: =H2/G2-1 -> 0.083946601 | I3: =I2/H2-1 -> 0.07407787 | J3: =J2/I2-1 -> 0.065267816 | ... M3: =M2/L2-1 -> 0.053518047
A5: Revenues by Geography
A6: EMEA | B6: 1498000 | C6: 1959900 | D6: 2322116 | E6: 2620004 | F6: =E6*(1+F11) -> 2882004.4 | G6: =F6*(1+G11) -> 3141384.8 | H6: =G6*(1+H11) -> 3392695.6 | I6: =H6*(1+I11) -> 3630184.3 | J6: =I6*(1+J11) -> 3847995.3 | K6: =J6*(1+K11) -> 4078875 | L6: =K6*(1+L11) -> 4282818.8 | M6: =L6*(1+M11) -> 4496959.7
A7: Americas | B7: 839000 | C7: 1311900 | D7: 1542978 | E7: 1714634 | F7: =E7*(1+F12) -> 1817512 | G7: =F7*(1+G12) -> 1981088.1 | H7: =G7*(1+H12) -> 2139575.2 | I7: =H7*(1+I12) -> 2289345.4 | J7: =I7*(1+J12) -> 2426706.2 | K7: =J7*(1+K12) -> 2572308.5 | L7: =K7*(1+L12) -> 2700924 | M7: =L7*(1+M12) -> 2835970.2
A8: APAC | B8: 248100 | C8: 347800 | D8: 438973 | E8: 455141 | F8: =E8*(1+F13) -> 500655.1 | G8: =F8*(1+G13) -> 560733.71 | H8: =G8*(1+H13) -> 628021.76 | I8: =H8*(1+I13) -> 697104.15 | J8: =I8*(1+J13) -> 773785.61 | K8: =J8*(1+K13) -> 851164.17 | L8: =K8*(1+L13) -> 927768.94 | M8: =L8*(1+M13) -> 1001990.5
A10: % YOY Growth
A11: EMEA | C11: =C6/B6-1 -> 0.30834446 | D11: =D6/C6-1 -> 0.18481351 | E11: =E6/D6-1 -> 0.128283 | F11: 0.1 | G11: 0.09 | H11: 0.08 | I11: 0.07 | J11: 0.06 | K11: 0.06 | L11: 0.05 | M11: 0.05
A12: Americas | C12: =C7/B7-1 -> 0.5636472 | D12: =D7/C7-1 -> 0.17613995 | E12: =E7/D7-1 -> 0.1112498 | F12: 0.06 | G12: 0.09 | H12: 0.08 | I12: 0.07 | J12: 0.06 | K12: 0.06 | L12: 0.05 | M12: 0.05
A13: APAC | C13: =C8/B8-1 -> 0.40185409 | D13: =D8/C8-1 -> 0.26214204 | E13: =E8/D8-1 -> 0.036831422 | F13: 0.1 | G13: 0.12 | H13: 0.12 | I13: 0.11 | J13: 0.11 | K13: 0.1 | L13: 0.09 | M13: 0.08
A15: % Share per Geography
A16: EMEA | B16: =B6/B$2 -> 0.57949441 | C16: =C6/C$2 -> 0.54146822 | D16: =D6/D$2 -> 0.53951669 | E16: =E6/E$2 -> 0.54699893 | F16: =F6/F$2 -> 0.55421333 | G16: =G6/G$2 -> 0.55274865 | H16: =H6/H$2 -> 0.55073612 | I16: =I6/I$2 -> 0.54864518 | ... M16: =M6/M$2 -> 0.53953242
A17: Americas | B17: =B7/B$2 -> 0.32456329 | C17: =C7/C$2 -> 0.36244306 | D17: =D7/D$2 -> 0.35849303 | E17: =E7/E$2 -> 0.35797769 | F17: =F7/F$2 -> 0.34951002 | G17: =G7/G$2 -> 0.34858633 | H17: =H7/H$2 -> 0.34731714 | I17: =I7/I$2 -> 0.34599851 | ... M17: =M7/M$2 -> 0.34025162
A18: APAC | B18: =B8/B$2 -> 0.095976344 | C18: =C8/C$2 -> 0.096087886 | D18: =D8/D$2 -> 0.10199028 | E18: =E8/E$2 -> 0.095023382 | F18: =F8/F$2 -> 0.096276651 | G18: =G8/G$2 -> 0.098665023 | H18: =H8/H$2 -> 0.10194674 | I18: =I8/I$2 -> 0.10535631 | ... M18: =M8/M$2 -> 0.12021596
M20: Calculations
M21: Historical Data
M22: Assumptions
M24: All figures in million euros

Sheet Financial Statements
B1: FY21 | C1: FY22 | D1: FY23 | E1: FY24 | F1: FY25E | G1: FY26E | H1: FY27E | I1: FY28E | J1: FY29E | K1: FY30E | L1: FY31E | M1: FY32E
A2: Net Revenues | B2: 2585012 | C2: 3619603 | D2: 4304067 | E2: 4789779 | F2: {='Revenue Prediction'!F2:M2} -> 5200171.5 | G2: 5683206.6 | H2: 6160292.5 | I2: 6616633.9 | J2: 7048487.1 | K2: 7502347.7 | L2: 7911511.7 | M2: 8334920.4
A3: % Change | C3: =C2/B2-1 -> 0.40022677 | D3: =D2/C2-1 -> 0.18909919 | E3: =E2/D2-1 -> 0.11284954 | F3: =F2/E2-1 -> 0.085680893 | G3: =G2/F2-1 -> 0.0928883 | H3: =H2/G2-1 -> 0.083946601 | I3: =I2/H2-1 -> 0.07407787 | J3: =J2/I2-1 -> 0.065267816 | ... M3: =M2/L2-1 -> 0.053518047
A4: Less: Cost of Sales | B4: 699906 | C4: 926969 | D4: 1088904 | E4: 1201679 | F4: =F2*F5 -> 1304639.9 | G4: =G2*G5 -> 1425825.7 | H4: =H2*H5 -> 1545518.9 | I4: =I2*I5 -> 1660007.7 | J4: =J2*J5 -> 1768352.8 | K4: =K2*K5 -> 1882219.1 | L4: =L2*L5 -> 1984871.8 | M4: =M2*M5 -> 2091098.3
A5: % of Revenue | B5: =B4/B2 -> 0.27075542 | C5: =C4/C2 -> 0.25609687 | D5: =D4/D2 -> 0.2529942 | E5: =E4/E2 -> 0.25088402 | F5: =E5 -> 0.25088402 | G5: =F5 -> 0.25088402 | H5: =G5 -> 0.25088402 | I5: =H5 -> 0.25088402 | J5: =I5 -> 0.25088402 | K5: =J5 -> 0.25088402 | L5: =K5 -> 0.25088402 | M5: =L5 -> 0.25088402
A6: Gross Profit | B6: =B2-B4 -> 1885106 | C6: =C2-C4 -> 2692634 | D6: =D2-D4 -> 3215163 | E6: =E2-E4 -> 3588100 | F6: =F2-F4 -> 3895531.6 | G6: =G2-G4 -> 4257380.9 | H6: =H2-H4 -> 4614773.6 | I6: =I2-I4 -> 4956626.2 | ... M6: =M2-M4 -> 6243822
A7: % Change | C7: =C6/B6-1 -> 0.42837273 | D7: =D6/C6-1 -> 0.19405868 | E7: =E6/D6-1 -> 0.11599319 | F7: =F6/E6-1 -> 0.085680893 | G7: =G6/F6-1 -> 0.0928883 | H7: =H6/G6-1 -> 0.083946601 | I7: =I6/H6-1 -> 0.07407787 | J7: =J6/I6-1 -> 0.065267816 | ... M7: =M6/L6-1 -> 0.053518047
A8: Less:
A9: Distribution Expense | B9: 138235 | C9: 221663 | D9: 217685 | E9: 220384 | F9: =F2*F10 -> 239266.7 | G9: =G2*G10 -> 261491.77 | H9: =H2*H10 -> 283443.12 | I9: =I2*I10 -> 304439.98 | J9: =J2*J10 -> 324310.12 | K9: =K2*K10 -> 345192.84 | L9: =L2*L10 -> 364019.01 | M9: =M2*M10 -> 383500.59
A10: % of Revenue | B10: =B9/B$2 -> 0.053475574 | C10: =C9/C$2 -> 0.061239589 | D10: =D9/D$2 -> 0.050576583 | E10: =E9/E$2 -> 0.046011309 | F10: =E10 -> 0.046011309 | G10: =F10 -> 0.046011309 | H10: =G10 -> 0.046011309 | I10: =H10 -> 0.046011309 | J10: =I10 -> 0.046011309 | K10: =J10 -> 0.046011309 | L10: =K10 -> 0.046011309 | M10: =L10 -> 0.046011309
A11: Advertising & Promotion Expenses | B11: 838962 | C11: 1099676 | D11: 1338144 | E11: 1551285 | F11: =F2*F12 -> 1642131 | G11: =G2*G12 -> 1794665.8 | H11: =H2*H12 -> 1945321.9 | I11: =I2*I12 -> 2089427.2 | J11: =J2*J12 -> 2225799.5 | K11: =K2*K12 -> 2369121.5 | L11: =L2*L12 -> 2498328.9 | M11: =M2*M12 -> 2632034.6
A12: % of Revenue | B12: =B11/B$2 -> 0.32454859 | C12: =C11/C$2 -> 0.30381122 | D12: =D11/D$2 -> 0.31090222 | E12: =E11/E$2 -> 0.32387402 | F12: =AVERAGE(B12:E12) -> 0.31578401 | G12: =F12 -> 0.31578401 | H12: =G12 -> 0.31578401 | I12: =H12 -> 0.31578401 | J12: =I12 -> 0.31578401 | K12: =J12 -> 0.31578401 | L12: =K12 -> 0.31578401 | M12: =L12 -> 0.31578401
A13: Selling, General & Administrative Expenses | B13: 556331 | C13: 834800 | D13: 966364 | E13: 1057717 | F13: =F2*F14 -> 1158596.3 | G13: =G2*G14 -> 1266216.3 | H13: =H2*H14 -> 1372510.9 | I13: =I2*I14 -> 1474183.6 | J13: =J2*J14 -> 1570400.3 | K13: =K2*K14 -> 1671520.3 | L13: =L2*L14 -> 1762681.9 | M13: =M2*M14 -> 1857017.1
A14: % of Revenue | B14: =B13/B$2 -> 0.21521409 | C14: =C13/C$2 -> 0.23063303 | D14: =D13/D$2 -> 0.22452346 | E14: =E13/E$2 -> 0.22082793 | F14: =AVERAGE(B14:E14) -> 0.22279963 | G14: =F14 -> 0.22279963 | H14: =G14 -> 0.22279963 | I14: =H14 -> 0.22279963 | J14: =I14 -> 0.22279963 | K14: =J14 -> 0.22279963 | L14: =K14 -> 0.22279963 | M14: =L14 -> 0.22279963
A16: Total Expenditure except Cost of Sales | B16: =B13+B11+B9 -> 1533528 | C16: =C13+C11+C9 -> 2156139 | D16: =D13+D11+D9 -> 2522193 | E16: =E13+E11+E9 -> 2829386 | F16: =F13+F11+F9 -> 3039994 | G16: =G13+G11+G9 -> 3322373.9 | H16: =H13+H11+H9 -> 3601275.9 | I16: =I13+I11+I9 -> 3868050.7 | ... M16: =M13+M11+M9 -> 4872552.3
A17: Operating Profit | B17: =B6-B16 -> 351578 | C17: =C6-C16 -> 536495 | D17: =D6-D16 -> 692970 | E17: =E6-E16 -> 758714 | F17: =F6-F16 -> 855537.59 | G17: =G6-G16 -> 935007.02 | H17: =H6-H16 -> 1013497.7 | I17: =I6-I16 -> 1088575.4 | ... M17: =M6-M16 -> 1371269.7
A18: % Change | C18: =C17/B17-1 -> 0.52596294 | D18: =D17/C17-1 -> 0.29166162 | E18: =E17/D17-1 -> 0.094872794 | F18: =F17/E17-1 -> 0.1276154 | G18: =G17/F17-1 -> 0.0928883 | H18: =H17/G17-1 -> 0.083946601 | I18: =I17/H17-1 -> 0.07407787 | J18: =J17/I17-1 -> 0.065267816 | ... M18: =M17/L17-1 -> 0.053518047
A19: Other Operational Income and Expenses | B19: 34951 | C19: -43528 | D19: -13764 | E19: -146626 | F19: 0 | G19: 0 | H19: 0 | I19: 0 | J19: 0 | K19: 0 | L19: 0 | M19: 0
A20: R&D Expense | F20: =-'CapEx Readjustments'!F10 -> -43058.993 | G20: =-'CapEx Readjustments'!G10 -> -47058.67 | H20: =-'CapEx Readjustments'!H10 -> -51009.085 | I20: =-'CapEx Readjustments'!I10 -> -54787.73 | J20: =-'CapEx Readjustments'!J10 -> -58363.605 | K20: =-'CapEx Readjustments'!K10 -> -62121.709 | L20: =-'CapEx Readjustments'!L10 -> -65509.71 | M20: =-'CapEx Readjustments'!M10 -> -69015.662
A21: Operational Profit | B21: =B17+B19 -> 386529 | C21: =C17+C19 -> 492967 | D21: =D17+D19 -> 679206 | E21: =E17+E19 -> 612088 | F21: =F17+F19+F20 -> 812478.6 | G21: =G17+G19+G20 -> 887948.35 | H21: =H17+H19+H20 -> 962488.6 | I21: =I17+I19+I20 -> 1033787.7 | J21: =J17+J19+J20 -> 1101260.8 | K21: =K17+K19+K20 -> 1172172.3 | L21: =L17+L19+L20 -> 1236100.4 | M21: =M17+M19+M20 -> 1302254
A22: % Change | C22: =C21/B21-1 -> 0.27536873 | D22: =D21/C21-1 -> 0.37779202 | E22: =E21/D21-1 -> -0.098818326 | F22: =F21/E21-1 -> 0.32738854 | G22: =G21/F21-1 -> 0.0928883 | H22: =H21/G21-1 -> 0.083946601 | I22: =I21/H21-1 -> 0.07407787 | J22: =J21/I21-1 -> 0.065267816 | ... M22: =M21/L21-1 -> 0.053518047
A23: Financial Result | B23: -62362 | C23: -34864 | D23: -87403 | E23: 19358 | F23: 0 | G23: 0 | H23: 0 | I23: 0 | J23: 0 | K23: 0 | L23: 0 | M23: 0
A24: Result from Associates and Joint Ventures and Impairment of Financial Assets | B24: 28494 | C24: 55621 | D24: 51347 | E24: 61060 | F24: 0 | G24: 0 | H24: 0 | I24: 0 | J24: 0 | K24: 0 | L24: 0 | M24: 0
A25: Profit Before Tax | B25: =B21+B23+B24 -> 352661 | C25: =C21+C23+C24 -> 513724 | D25: =D21+D23+D24 -> 643150 | E25: =E21+E23+E24 -> 692506 | F25: =F21+F23+F24 -> 812478.6 | G25: =G21+G23+G24 -> 887948.35 | H25: =H21+H23+H24 -> 962488.6 | I25: =I21+I23+I24 -> 1033787.7 | ... M25: =M21+M23+M24 -> 1302254
A26: % Change | C26: =C25/B25-1 -> 0.45670772 | D26: =D25/C25-1 -> 0.25193684 | E26: =E25/D25-1 -> 0.07674104 | F26: =F25/E25-1 -> 0.17324413 | G26: =G25/F25-1 -> 0.0928883 | H26: =H25/G25-1 -> 0.083946601 | I26: =I25/H25-1 -> 0.07407787 | J26: =J25/I25-1 -> 0.065267816 | ... M26: =M25/L25-1 -> 0.053518047
A27: Less: Income Tax | B27: 153745 | C27: 101201 | D27: 143262 | E27: 149973 | F27: =F25*F28 -> 203119.65 | G27: =G25*G28 -> 221987.09 | H27: =H25*H28 -> 240622.15 | I27: =I25*I28 -> 258446.93 | J27: =J25*J28 -> 275315.19 | K27: =K25*K28 -> 293043.07 | L27: =L25*L28 -> 309025.09 | M27: =M25*M28 -> 325563.51
A28: Effective Tax Rate | B28: =B27/B25 -> 0.43595691 | C28: =C27/C25 -> 0.19699488 | D28: =D27/D25 -> 0.22275052 | E28: =E27/E25 -> 0.21656563 | F28: 0.25 | G28: 0.25 | H28: 0.25 | I28: 0.25 | J28: 0.25 | K28: 0.25 | L28: 0.25 | M28: 0.25
A29: Net Profit for the Year | B29: =B25-B27 -> 198916 | C29: =C25-C27 -> 412523 | D29: =D25-D27 -> 499888 | E29: =E25-E27 -> 542533 | F29: =F25-F27 -> 609358.95 | G29: =G25-G27 -> 665961.27 | H29: =H25-H27 -> 721866.45 | I29: =I25-I27 -> 775340.78 | ... M29: =M25-M27 -> 976690.53
A30: Less: Non-Controlling Interests | B30: 22123 | C30: -13033 | D30: -34679 | E30: -11884 | F30: 0 | G30: 0 | H30: 0 | I30: 0 | J30: 0 | K30: 0 | L30: 0 | M30: 0
A31: Net Profit Attributable to the Parent Company | B31: =B29+B30 -> 221039 | C31: =C29+C30 -> 399490 | D31: =D29+D30 -> 465209 | E31: =E29+E30 -> 530649 | F31: =F29+F30 -> 609358.95 | G31: =G29+G30 -> 665961.27 | H31: =H29+H30 -> 721866.45 | I31: =I29+I30 -> 775340.78 | ... M31: =M29+M30 -> 976690.53
A32: % Change | C32: =C31/B31-1 -> 0.80732812 | D32: =D31/C31-1 -> 0.16450725 | E32: =E31/D31-1 -> 0.14066796 | F32: =F31/E31-1 -> 0.14832771 | G32: =G31/F31-1 -> 0.0928883 | H32: =H31/G31-1 -> 0.083946601 | I32: =I31/H31-1 -> 0.07407787 | J32: =J31/I31-1 -> 0.065267816 | ... M32: =M31/L31-1 -> 0.053518047
A33: Adjusted Net Profit | F33: =F31+'CapEx Readjustments'!F10-'CapEx Readjustments'!F13 -> 630741.63 | G33: =G31+'CapEx Readjustments'!G10-'CapEx Readjustments'!G13 -> 685997.95 | H33: =H31+'CapEx Readjustments'!H10-'CapEx Readjustments'!H13 -> 740844.38 | I33: =I31+'CapEx Readjustments'!I10-'CapEx Readjustments'!I13 -> 793352.87 | J33: =J31+'CapEx Readjustments'!J10-'CapEx Readjustments'!J13 -> 843030.52 | K33: =K31+'CapEx Readjustments'!K10-'CapEx Readjustments'!K13 -> 895701.03 | L33: =L31+'CapEx Readjustments'!L10-'CapEx Readjustments'!L13 -> 942892.13 | M33: =M31+'CapEx Readjustments'!M10-'CapEx Readjustments'!M13 -> 992059.13
A36: ASSETS
A37: Property, Plant, and Equipment | B37: 210971 | C37: 271094 | D37: 326341 | E37: 380356 | F37: =E37-F119-F92 -> 485774.91 | G37: =F37-G119-G92 -> 583771.48 | H37: =G37-H119-H92 -> 675941.25 | I37: =H37-I119-I92 -> 762922.13 | J37: =I37-J119-J92 -> 845052.24 | K37: =J37-K119-K92 -> 924364.47 | L37: =K37-L119-L92 -> 999841.86 | M37: =L37-M119-M92 -> 1072971
A38: Intangible Assets | B38: 2660758 | C38: 4062277 | D38: 4114267 | E38: 4705720 | F38: =E38-F124-F94 -> 5038849.1 | G38: =F38-G124-G94 -> 5403831.4 | H38: =G38-H124-H94 -> 5799960 | I38: =H38-I124-I94 -> 6225469.5 | J38: =I38-J124-J94 -> 6678340.4 | K38: =J38-K124-K94 -> 7159917.4 | L38: =K38-L124-L94 -> 7666732.3 | M38: =L38-M124-M94 -> 8199589.9
A39: R&D Asset | F39: ='CapEx Readjustments'!F14 -> 108087.93 | G39: ='CapEx Readjustments'!G14 -> 128124.62 | H39: ='CapEx Readjustments'!H14 -> 147102.55 | I39: ='CapEx Readjustments'!I14 -> 165114.64 | J39: ='CapEx Readjustments'!J14 -> 182199.59 | K39: ='CapEx Readjustments'!K14 -> 198771.4 | L39: ='CapEx Readjustments'!L14 -> 214588.26 | M39: ='CapEx Readjustments'!M14 -> 229956.86
A40: Right-of-use Assets | B40: 188653 | C40: 239873 | D40: 287922 | E40: 365076 | F40: =E40-F96 -> 289155 | G40: =F40-G96 -> 229022.49 | H40: =G40-H96 -> 181395.1 | I40: =H40-I96 -> 143672.28 | J40: =I40-J96 -> 113794.27 | K40: =J40-K96 -> 90129.678 | L40: =K40-L96 -> 71386.361 | M40: =L40-M96 -> 56540.893
A41: Investments in Associates and Joint Ventures | B41: 346456 | C41: 344824 | D41: 375212 | E41: 395190 | F41: =E41+F125 -> 395190 | G41: =F41+G125 -> 395190 | H41: =G41+H125 -> 395190 | I41: =H41+I125 -> 395190 | J41: =I41+J125 -> 395190 | K41: =J41+K125 -> 395190 | L41: =K41+L125 -> 395190 | M41: =L41+M125 -> 395190
A42: Financial Investments | B42: 9595 | C42: 14154 | D42: 16359 | E42: 689 | F42: =E42+F123 -> 689 | G42: =F42+G123 -> 689 | H42: =G42+H123 -> 689 | I42: =H42+I123 -> 689 | J42: =I42+J123 -> 689 | K42: =J42+K123 -> 689 | L42: =K42+L123 -> 689 | M42: =L42+M123 -> 689
A43: Other Non-current Assets | B43: 62637 | C43: 102615 | D43: 131444 | E43: 130865 | F43: =E43 -> 130865 | G43: =F43 -> 130865 | H43: =G43 -> 130865 | I43: =H43 -> 130865 | J43: =I43 -> 130865 | K43: =J43 -> 130865 | L43: =K43 -> 130865 | M43: =L43 -> 130865
...

Sheet CapEx Readjustments
C1: Assumed Life (in Years) | E1: 4
B2: 2021 | C2: 2022 | D2: 2023 | E2: 2024 | F2: 2025 | G2: 2026 | H2: 2027 | I2: 2028 | J2: 2029 | K2: 2030 | L2: 2031 | M2: 2032
A3: Acquisitions Normalization
A4: Acquisition Expense | B4: =-'Financial Statements'!B124 -> -4368 | C4: =-'Financial Statements'!C124 -> 840189 | D4: =-'Financial Statements'!D124 -> 0 | E4: =-'Financial Statements'!E124 -> 265288 | F4: =F5*'Revenue Prediction'!F2 -> 374283.12 | G4: =G5*'Revenue Prediction'!G2 -> 409049.64 | H4: =H5*'Revenue Prediction'!H2 -> 443387.97 | I4: =I5*'Revenue Prediction'!I2 -> 476233.2 | J4: =J5*'Revenue Prediction'!J2 -> 507315.9 | K4: =K5*'Revenue Prediction'!K2 -> 539982.59 | L4: =L5*'Revenue Prediction'!L2 -> 569432.23 | M4: =M5*'Revenue Prediction'!M2 -> 599907.13
A5: % of Revenue | B5: =B4/'Financial Statements'!B2 -> -0.0016897407 | C5: =C4/'Financial Statements'!C2 -> 0.23212187 | D5: =D4/'Financial Statements'!D2 -> 0 | E5: =E4/'Financial Statements'!E2 -> 0.055386271 | F5: =AVERAGE(B4:E4)/AVERAGE('Revenue Prediction'!B2:E2) -> 0.071975148 | G5: =F5 -> 0.071975148 | H5: =G5 -> 0.071975148 | I5: =H5 -> 0.071975148 | J5: =I5 -> 0.071975148 | K5: =J5 -> 0.071975148 | L5: =K5 -> 0.071975148 | M5: =L5 -> 0.071975148
A6: Amortization of Acquisition | B6: ='Financial Statements'!B94 -> 19567 | C6: ='Financial Statements'!C94 -> 26966 | D6: ='Financial Statements'!D94 -> 32903 | E6: ='Financial Statements'!E94 -> 41154 | F6: =F4*F7 -> 3244.9244 | G6: =G4*G7 -> 3546.3399 | H6: =H4*H7 -> 3844.0431 | I6: =I4*I7 -> 4128.8017 | J6: =J4*J7 -> 4398.2795 | K6: =K4*K7 -> 4681.4901 | L6: =L4*L7 -> 4936.8098 | M6: =M4*M7 -> 5201.0182
A7: Amortization % | B7: =B6/(B6+'Financial Statements'!B38) -> 0.0073002341 | C7: =C6/(C6+'Financial Statements'!C38) -> 0.0065943746 | D7: =D6/(D6+'Financial Statements'!D38) -> 0.007933844 | E7: =E6/(E6+'Financial Statements'!E38) -> 0.0086697056 | F7: =E7 -> 0.0086697056 | G7: =F7 -> 0.0086697056 | H7: =G7 -> 0.0086697056 | I7: =H7 -> 0.0086697056 | J7: =I7 -> 0.0086697056 | K7: =J7 -> 0.0086697056 | L7: =K7 -> 0.0086697056 | M7: =L7 -> 0.0086697056
B9: -4 | C9: -3 | D9: -2 | E9: -1 | F9: 0
A10: R&D Expense | B10: 22677 | C10: 28592 | D10: 33208 | E10: 41834 | F10: ='Revenue Prediction'!F2*'CapEx Readjustments'!F11 -> 43058.993 | G10: ='Revenue Prediction'!G2*'CapEx Readjustments'!G11 -> 47058.67 | H10: ='Revenue Prediction'!H2*'CapEx Readjustments'!H11 -> 51009.085 | I10: ='Revenue Prediction'!I2*'CapEx Readjustments'!I11 -> 54787.73 | J10: ='Revenue Prediction'!J2*'CapEx Readjustments'!J11 -> 58363.605 | K10: ='Revenue Prediction'!K2*'CapEx Readjustments'!K11 -> 62121.709 | L10: ='Revenue Prediction'!L2*'CapEx Readjustments'!L11 -> 65509.71 | M10: ='Revenue Prediction'!M2*'CapEx Readjustments'!M11 -> 69015.662
A11: % of Revenue | B11: =B10/'Financial Statements'!B2 -> 0.0087724931 | C11: =C10/'Financial Statements'!C2 -> 0.0078992088 | D11: =D10/'Financial Statements'!D2 -> 0.0077154933 | E11: =E10/'Financial Statements'!E2 -> 0.0087340147 | F11: =AVERAGE(B11:E11) -> 0.0082803025 | G11: =F11 -> 0.0082803025 | H11: =G11 -> 0.0082803025 | I11: =H11 -> 0.0082803025 | J11: =I11 -> 0.0082803025 | K11: =J11 -> 0.0082803025 | L11: =K11 -> 0.0082803025 | M11: =L11 -> 0.0082803025
A12: Unamortized at Beginning of 0 | B12: =B10*(1-(3/4)) -> 5669.25 | C12: =C10*(1-(2/4)) -> 14296 | D12: =D10*(1-(1/4)) -> 24906 | E12: =E10 -> 41834 | F12: =SUM(B12:E12) -> 86705.25 | G12: =F14 -> 108087.93 | H12: =G14 -> 128124.62 | I12: =H14 -> 147102.55 | J12: =I14 -> 165114.64 | K12: =J14 -> 182199.59 | L12: =K14 -> 198771.4 | M12: =L14 -> 214588.26
A13: Amortization | F13: =F12/4 -> 21676.312 | G13: =G12/4 -> 27021.983 | H13: =H12/4 -> 32031.155 | I13: =I12/4 -> 36775.637 | J13: =J12/4 -> 41278.66 | K13: =K12/4 -> 45549.897 | L13: =L12/4 -> 49692.85 | M13: =M12/4 -> 53647.065
A14: Unamortized at End of Year | F14: =F12-F13+F10 -> 108087.93 | G14: =G12-G13+G10 -> 128124.62 | H14: =H12-H13+H10 -> 147102.55 | I14: =I12-I13+I10 -> 165114.64 | J14: =J12-J13+J10 -> 182199.59 | K14: =K12-K13+K10 -> 198771.4 | L14: =L12-L13+L10 -> 214588.26 | M14: =M12-M13+M10 -> 229956.86
A15: Capex | F15: =F10-F13 -> 21382.681 | G15: =G10-G13 -> 20036.687 | H15: =H10-H13 -> 18977.931 | I15: =I10-I13 -> 18012.092 | J15: =J10-J13 -> 17084.945 | K15: =K10-K13 -> 16571.812 | L15: =L10-L13 -> 15816.86 | M15: =M10-M13 -> 15368.597
M17: Historical Data
M18: Assumptions
M20: All figures in million euros

Sheet Beta
A1: Source - Beta | B1: Bloomberg | D1: Tax rate | E1: 0.25
A2: Source - Financials | B2: Yahoo Finance
A5: ELF Beauty Inc | B5: 2024 | C5: 2023 | D5: 2022 | E5: 2021 | G5: Unlevered Beta | H5: Business Beta | I5: Operating Asset Beta
A7: Revenue | B7: 1313517 | C7: 1023932 | D7: 578844 | E7: 392155
A8: Operating Profit | B8: 158027 | C8: 149678 | D8: 68143 | E8: 29820
A9: Change in Operating Income % | B9: =B8/C8-1 -> 0.055779741 | C9: =C8/D8-1 -> 1.1965279 | D9: =D8/E8-1 -> 1.2851442
A10: Change in Revenue % | B10: =B7/C7-1 -> 0.28281663 | C10: =C7/D7-1 -> 0.76892565 | D10: =D7/E7-1 -> 0.47605921
A11: Operating Leverage | B11: =AVERAGE(B9:D9)/AVERAGE(B10:D10) -> 1.6608518
A13: Market Cap | B13: 6670000
A14: Debt | B14: 313018
A15: Cash | B15: 148692
A16: Beta | B16: 1.51 | G16: =B16/(1+(B14/B13)*(1-$E$1)) -> 1.4586597 | H16: =G16/B11 -> 0.87825999 | I16: =H16/(1-(B15/(B14+B13))) -> 0.89736798
A19: Proya Cosmetics | B19: Currency | C19: CNY
A21: Revenue | B21: 10778412 | C21: 8904573.5 | D21: 6385451.4 | E21: 4633150.5
A22: Operating Profit | B22: 1958959 | C22: 1580285.3 | D22: 1192128.6 | E22: 749666.62
A23: % Change Operating Profit | B23: =B22/C22-1 -> 0.23962363 | C23: =C22/D22-1 -> 0.32559967 | D23: =D22/E22-1 -> 0.59021167
A24: % Change Revenue | B24: =B21/C21-1 -> 0.21043549 | C24: =C21/D21-1 -> 0.39450963 | D24: =D21/E21-1 -> 0.37820936
A25: Operating Leverage | B25: =AVERAGE(B23:D23)/AVERAGE(B24:D24) -> 1.1752324
A27: Market Cap | B27: 32857000
A28: Debt | B28: 794440.48
A29: Cash | B29: 4082126.4
A30: Beta | B30: 0.31 | G30: =B30/(1+(B28/B27)*(1-$E$1)) -> 0.30447857 | H30: =G30/B25 -> 0.25907946 | I30: =H30/(1-(B29/(B28+B27))) -> 0.2948461
A32: Coty INC CLA
A34: Revenue | B34: 6118000 | C34: 5554100 | D34: 5304400 | E34: 4629900
A35: Operating Income | B35: 583400 | C35: 537200 | D35: 280500 | E35: 153800
A36: % Change Operating Income | B36: =B35/C35-1 -> 0.086001489 | C36: =C35/D35-1 -> 0.91515152 | D36: =D35/E35-1 -> 0.82379714
A37: % Change Revenue | B37: =B34/C34-1 -> 0.1015286 | C37: =C34/D34-1 -> 0.047074127 | D37: =D34/E34-1 -> 0.14568349
A38: Operating Leverage | B38: =AVERAGE(B36:D36)/AVERAGE(B37:D37) -> 6.2012762
A40: Market CAP | B40: 4313000
A41: Debt | B41: 4121300
A42: Cash | B42: 300800
A43: Beta | B43: 1.9 | G43: =B43/(1+(B41/B40)*(1-$E$1)) -> 1.1067974 | H43: =G43/B38 -> 0.17847896 | I43: =H43/(1-(B42/(B41+B40))) -> 0.18507962
A45: Interparfums US
A46: Revenue | B46: 1452325 | C46: 1317675 | D46: 1086653 | E46: 879516
A47: Operating Income | B47: 278801 | C47: 251382 | D47: 202052 | E47: 150443
A48: % Change Operating Income | B48: =B47/C47-1 -> 0.10907304 | C48: =C47/D47-1 -> 0.24414507 | D48: =D47/E47-1 -> 0.34304687
A49: % Change Revenue | B49: =B46/C46-1 -> 0.10218757 | C49: =C46/D46-1 -> 0.21259961 | D49: =D46/E46-1 -> 0.23551249
A50: Operating Leverage | B50: =AVERAGE(B48:D48)/AVERAGE(B49:D49) -> 1.265247
A52: Market Cap | B52: 4156000
A53: Debt | B53: 192194
...

Sheet Mature MRP
A1: ROE is estimated
A2: Discount Rate | B2: 0.07989265 | C2: Rm
A3: Government Bond Yield | B3: 0.02716 | C3: Source: https://www.investing.com/rates-bonds/germany-10-year-bond-yield
A5: Measure | B5: 0 | C5: 1 | D5: 2 | E5: 3
A6: Earnings Per Share | B6: 1312.63 | C6: 1479.55 | D6: 1667.66 | E6: 1896.3 | F6: =E6*(1+F9) -> 1947.8794
A7: Book Value Per Share | B7: 11943.75 | C7: 13030.39 | D7: 14000.37 | E7: 14832.72
A8: ROE Estimated | C8: =C6/B7 -> 0.1238765 | D8: =D6/C7 -> 0.12798236 | E8: =E6/D7 -> 0.13544642 | F8: =AVERAGE(C8:E8) -> 0.12910176
A9: Growth | C9: =C6/B6-1 -> 0.12716455 | D9: =D6/C6-1 -> 0.12714001 | E9: =E6/D6-1 -> 0.13710229 | F9: 0.0272 | G9: 0.0272
A10: Equity Reinvestment rate | C10: =D9/C8 -> 1.0263448 | D10: =E9/D8 -> 1.0712593 | E10: =F9/E8 -> 0.20081741 | F10: =G9/F8 -> 0.21068652
A11: FCFE | C11: =C6*(1-C10) -> -38.97848 | D11: =D6*(1-D10) -> -118.83627 | E11: =E6*(1-E10) -> 1515.4899 | F11: =F6*(1-F10) -> 1537.4874
A12: Terminal Value | E12: =F11/(B2-B3) -> 29156.271
A13: Cash flow | C13: =SUM(C11:C12) -> -38.97848 | D13: =SUM(D11:D12) -> -118.83627 | E13: =SUM(E11:E12) -> 30671.761
A14: Present value of future FCFE | C14: =C13/((1+$B$2)^C5) -> -36.094773 | D14: =D13/((1+$B$2)^D5) -> -101.9032 | E14: =E13/((1+$B$2)^E5) -> 24355.495
A15: NPV | B15: =SUM(C14:E14) -> 24217.497
A16: Index Value | B16: 24217.5
H17: Historical Data
A18: MMRP | B18: =B2-B3 -> 0.05273265 | H18: Assumptions

Sheet Geography CRP & Lambda
A1: Country | B1: GDP (in Millions)
A2: Angola | B2: 84722.958 | C2: 30456.567
A3: Benin | B3: 19673.285 | C3: 4047.3638 | G3: GDP | H3: Exports | I3: Exports to GDP Ratio | J3: Average Domestic Consumption | K3: Puig Regional Revenue % | L3: Lambda | M3: CRP | N3: Weight of GDP | O3: CRP * Weight
A4: Botswana | B4: 19395.765 | C4: 5053.3186 | F4: Africa | G4: 2349249.4 | H4: 639236.34 | M4: =VLOOKUP(F4,'[1]Damodaran CRP by Country'!$A$2:$E$167,3,0) -> 0.02359997 | N4: =G4/$G$8 -> 0.076820708 | O4: =M4*N4 -> 0.0018129664
A5: Burkina Faso | B5: 20324.618 | C5: 6623.3648 | F5: Middle East | G5: 3109419.4 | H5: 1613802.7 | M5: =VLOOKUP(F5,'[1]Damodaran CRP by Country'!$A$2:$E$167,3,0) -> 0.023271353 | N5: =G5/$G$8 -> 0.10167835 | O5: =M5*N5 -> 0.0023661927
A6: Cameroon | B6: 47945.51 | C6: 7564.1228 | F6: Eastern Europe | G6: 3172972.5 | H6: 1762405.7 | M6: =VLOOKUP(F6,'[1]Damodaran CRP by Country'!$A$2:$E$167,3,0) -> 0.037600057 | N6: =G6/$G$8 -> 0.10375654 | O6: =M6*N6 -> 0.0039012519
A7: Cape Verde | B7: 1936 | C7: 917.99624 | F7: Western Europe | G7: 21949298 | H7: 10708723 | M7: =VLOOKUP(F7,'[1]Damodaran CRP by Country'!$A$2:$E$167,3,0) -> 0.012240226 | N7: =G7/$G$8 -> 0.7177444 | O7: =M7*N7 -> 0.008785354
A8: Congo (Democratic Republic of) | B8: 66383.287 | C8: 32984.602 | F8: EMEA | G8: =SUM(G4:G7) -> 30580939 | H8: =SUM(H4:H7) -> 14724168 | I8: =H8/G8 -> 0.48148187 | J8: =1-I8 -> 0.51851813 | K8: =AVERAGE('Revenue Prediction'!F16:M16) -> 0.54710347 | L8: =K8/J8 -> 1.0551289 | M8: =SUM(O4:O7) -> 0.016865765
A9: Congo (Republic of) | B9: 15321.056 | C9: 8296.9525 | F9: Central and South America | G9: 6318352.5 | H9: 1660027.6 | M9: =VLOOKUP(F9,'[1]Damodaran CRP by Country'!$A$2:$E$167,3,0) -> 0.050924919 | N9: =G9/$G$12 -> 0.17467531 | O9: =M9*N9 -> 0.0088953261
A10: Côte d'Ivoire | B10: 78788.829 | C10: 23882.966 | F10: North America | G10: 29501021 | H10: 3907781.7 | M10: =VLOOKUP(F10,'[1]Damodaran CRP by Country'!$A$2:$E$167,3,0) -> 0.0037403298 | N10: =G10/$G$12 -> 0.81557652 | O10: =M10*N10 -> 0.0030505251
A11: Egypt | B11: 395926.08 | C11: 79983.635 | F11: Caribbean | G11: 352610.57 | H11: 75906.469 | M11: =VLOOKUP(F11,'[1]Damodaran CRP by Country'!$A$2:$E$167,3,0) -> 0.089534906 | N11: =G11/$G$12 -> 0.0097481679 | O11: =M11*N11 -> 0.0008728013
A12: Ethiopia | B12: 163697.93 | C12: 10451.092 | F12: Americas | G12: =SUM(G9:G11) -> 36171984 | H12: =SUM(H9:H11) -> 5643715.8 | I12: =H12/G12 -> 0.1560245 | J12: =1-I12 -> 0.8439755 | K12: =AVERAGE('Revenue Prediction'!F17:M17) -> 0.34502624 | L12: =K12/J12 -> 0.40881073 | M12: =SUM(O9:O11) -> 0.012818653
A13: Gabon | B13: 20516.134 | C13: 13621.52 | F13: Asia | G13: 33158417 | H13: 9887824.9 | M13: =VLOOKUP(F13,'[1]Damodaran CRP by Country'!$A$2:$E$167,3,0) -> 0.017068463 | N13: =G13/$G$15 -> 0.94368614 | O13: =M13*N13 -> 0.016107272
A14: Ghana | B14: 76370.394 | C14: 29197.466 | F14: Australia & New Zealand | G14: 1978706.9 | H14: 493583.29 | M14: =VLOOKUP(F14,'[1]Damodaran CRP by Country'!$A$2:$E$167,3,0) -> 4.758694e-05 | N14: =G14/$G$15 -> 0.056313856 | O14: =M14*N14 -> 2.6798041e-06
A15: Kenya | B15: 107440.58 | C15: 13865.029 | F15: APAC | G15: =SUM(G13:G14) -> 35137123 | H15: =SUM(H13:H14) -> 10381408 | I15: =H15/G15 -> 0.29545413 | J15: =1-I15 -> 0.70454587 | K15: =AVERAGE('Revenue Prediction'!F18:M18) -> 0.10787029 | L15: =K15/J15 -> 0.15310613 | M15: =SUM(O13:O14) -> 0.016109952
A16: Mali | B16: 20904.898 | C16: 5986.892
A17: Mauritius | B17: 14397.127 | C17: 6908.9787
A18: Morocco | B18: 141109.37 | C18: 66846.859
A19: Mozambique | B19: 20624.598 | C19: 9579.5494
A20: Namibia | B20: 12351.025 | C20: 5568.7655
A21: Niger | B21: 16819.17 | C21: 6086.7484
A22: Nigeria | B22: 362814.95 | C22: 64001.156
A23: Rwanda | B23: 14097.769 | C23: 4392.6526
A24: Senegal | B24: 31013.986 | C24: 9053.0821
A25: South Africa | B25: 377781.6 | C25: 127482.42
A26: Swaziland | B26: 4597.8558 | C26: 2137
A27: Tanzania | B27: 79158.286 | C27: 15622.428
... A31: Zambia | B31: 28162.631 | C31: 11264.526
A32: Africa | B32: =SUM(B2:B31) -> 2349249.4 | C32: =SUM(C2:C31) -> 639236.34
A33: Bangladesh | B33: 437415.33 | C33: 47087.839
A34: Cambodia | B34: 31772.76 | C34: 33078.91
A35: China | B35: 17794782 | C35: 3753056.1
A36: Fiji | B36: 5494.7975 | C36: 3100.1389
A37: Hong Kong | B37: 382054.57 | C37: 660362.37
A38: India | B38: 3549918.9 | C38: 828633.46
A39: Indonesia | B39: 1371171.2 | C39: 309745.62
A40: Japan | B40: 4212945.2 | C40: 920644.08
A41: Korea | B41: 1712792.9 | C41: 570645.71
A42: Laos | B42: 15843.156 | C42: 2218
A43: Macao | B43: 47061.844 | C43: 536.128
...

Sheet Damodaran CRP by Country
A1: Country | B1: GDP (in Millions) | C1: Country Risk Premium | D1: GDP Weight
A2: Angola | B2: 84722.958 | C2: 0.032513421 | D2: 0.036063841 | E2: =D2*C2 -> 0.0011725589
A3: Benin | B3: 19673.285 | C3: 0.023646125 | D3: 0.0083742852 | E3: =D3*C3 -> 0.00019801939
A4: Botswana | B4: 19395.765 | C4: 0.0073024796 | D4: 0.008256154 | E4: =D4*C4 -> 6.0290397e-05
A5: Burkina Faso | B5: 20324.618 | D5: 0.0086515368 | E5: =D5*C5 -> 0
A6: Cameroon | B6: 47945.51 | D6: 0.020408863 | E6: =D6*C6 -> 0
A7: Cape Verde | B7: 1936 | C7: 0.028166707 | D7: 0.000824093 | E7: =D7*C7 -> 2.3211986e-05
A8: Congo (Democratic Republic of) | B8: 66383.287 | C8: 0.032513421 | D8: 0.028257232 | E8: =D8*C8 -> 0.0009187393
A9: Congo (Republic of) | B9: 15321.056 | D9: 0.0065216812 | E9: =D9*C9 -> 0
A10: Côte d'Ivoire | B10: 78788.829 | C10: 0.044510352 | D10: 0.033537873 | E10: =D10*C10 -> 0.0014927825
A11: Egypt | B11: 395926.08 | D11: 0.16853301 | E11: =D11*C11 -> 0
A12: Ethiopia | B12: 163697.93 | D12: 0.069680948 | E12: =D12*C12 -> 0
A13: Gabon | B13: 20516.134 | D13: 0.0087330592 | E13: =D13*C13 -> 0
A14: Ghana | B14: 76370.394 | D14: 0.032508423 | E14: =D14*C14 -> 0
A15: Kenya | B15: 107440.58 | D15: 0.045734001 | E15: =D15*C15 -> 0
A16: Mali | B16: 20904.898 | D16: 0.0088985435 | E16: =D16*C16 -> 0
A17: Mauritius | B17: 14397.127 | C17: 0.096149315 | D17: 0.0061283945 | E17: =D17*C17 -> 0.00058924094
A18: Morocco | B18: 141109.37 | C18: 0.037034004 | D18: 0.060065726 | E18: =D18*C18 -> 0.0022244743
A19: Mozambique | B19: 20624.598 | C19: 0.14796215 | D19: 0.0087792286 | E19: =D19*C19 -> 0.0012989935
A20: Namibia | B20: 12351.025 | C20: 0.023646125 | D20: 0.0052574344 | E20: =D20*C20 -> 0.00012431795
A21: Niger | B21: 16819.17 | C21: 0.14796215 | D21: 0.0071593805 | E21: =D21*C21 -> 0.0010593173
A22: Nigeria | B22: 362814.95 | C22: 0.032513421 | D22: 0.15443867 | E22: =D22*C22 -> 0.0050213295
A23: Rwanda | B23: 14097.769 | C23: 0.028166707 | D23: 0.0060009672 | E23: =D23*C23 -> 0.00016902748
A24: Senegal | B24: 31013.986 | C24: 0.032513421 | D24: 0.013201658 | E24: =D24*C24 -> 0.00042923105
A25: South Africa | B25: 377781.6 | C25: 0.044510352 | D25: 0.16080949 | E25: =D25*C25 -> 0.007157687
A26: Swaziland | B26: 4597.8558 | C26: 0.028166707 | D26: 0.0019571595 | E26: =D26*C26 -> 5.5126739e-05
A27: Tanzania | B27: 79158.286 | C27: 0.023646125 | D27: 0.033695139 | E27: =D27*C27 -> 0.00079675946
A28: Togo | B28: 9171.2618 | C28: 0.032513421 | D28: 0.0039039115 | E28: =D28*C28 -> 0.00012692952
A29: Tunisia | B29: 48529.595 | D29: 0.02065749 | E29: =D29*C29 -> 0
A30: Uganda | B30: 49272.882 | C30: 0.032513421 | D30: 0.020973883 | E30: =D30*C30 -> 0.00068193269
A31: Zambia | B31: 28162.631 | D31: 0.011987927 | E31: =D31*C31 -> 0
A32: Africa | B32: 2349249.4 | C32: =SUM(E2:E31) -> 0.02359997 | D32: 1 | E32: =D32*C32 -> 0.02359997
A33: Bangladesh | B33: 437415.33 | C33: 0.081370487 | D33: 0.013191683 | E33: =D33*C33 -> 0.0010734137
A34: Cambodia | B34: 31772.76 | C34: 0.081370487 | D34: 0.00095821102 | E34: =D34*C34 -> 7.7970097e-05
A35: China | B35: 17794782 | C35: 0.010432114 | D35: 0.53665958 | E35: =D35*C35 -> 0.0055984938
A36: Fiji | B36: 5494.7975 | C36: 0.06659166 | D36: 0.00016571351 | E36: =D36*C36 -> 1.1035138e-05
A37: Hong Kong | B37: 382054.57 | C37: 0.0088672967 | D37: 0.011522099 | E37: =D37*C37 -> 0.00010216987
A38: India | B38: 3549918.9 | C38: 0.032513421 | D38: 0.10705936 | E38: =D38*C38 -> 0.0034808661
A39: Indonesia | B39: 1371171.2 | C39: 0.028166707 | D39: 0.04135213 | E39: =D39*C39 -> 0.0011647533
A40: Japan | B40: 4212945.2 | C40: 0.010432114 | D40: 0.12705508 | E40: =D40*C40 -> 0.001325453
...

Sheet WACC
A1: Spain Risk-free Rate
A2: Germany 10 Year Bund Yield | B2: 0.0272 | C2: Source: https://www.investing.com/rates-bonds/germany-10-year-bond-yield | E2: Debt | F2: ='Financial Statements'!E68+'Financial Statements'!E64 -> 1657104
A3: Adjusted default spread | E3: Equity | F3: ='Financial Statements'!F54+'Financial Statements'!E55+'Financial Statements'!E60 -> 3740673
A4: Moody's Rating | B4: Baa1 | E4: D+E | F4: =F3+F2 -> 5397777
A5: Associated Adjusted default spread | B5: 0.0158 | C5: Source: https://pages.stern.nyu.edu/~adamodar/New_Home_Page/datafile/ctryprem.html | E5: Tax Rate | F5: 0.25
A6: Risk-free Rate | B6: =B5+B2 -> 0.043
E7: Wacc | F7: =(F3/F4*B18)+(F2/F4*B24*(1-F5)) -> 0.090262332
A8: Cost of Equity Calculation
A9: Rf | B9: =B6 -> 0.043
A10: MMRP | B10: ='Mature MRP'!B18 -> 0.05273265
A11: Beta | B11: =Beta!B110 -> 0.80233504
A12: EMEA CRP | B12: ='Geography CRP & Lambda'!M8 -> 0.016865765
A13: EMEA Lambda | B13: ='Geography CRP & Lambda'!L8 -> 1.0551289
A14: Americas CRP | B14: ='Geography CRP & Lambda'!M12 -> 0.012818653
A15: Americas Lambda | B15: ='Geography CRP & Lambda'!L12 -> 0.40881073
A16: APAC CRP | B16: ='Geography CRP & Lambda'!M15 -> 0.016109952
A17: APAC Lambda | B17: ='Geography CRP & Lambda'!L15 -> 0.15310613
A18: Cost of Equity | B18: =B9+(B11*B10)+(B13*B12)+(B15*B14)+(B17*B16) -> 0.11081174
A20: Cost of Debt
A21: Moody's Rating | B21: Baa1
A22: Associated Default risk | B22: 0.0155 | C22: source: https://pages.stern.nyu.edu/~adamodar/New_Home_Page/datafile/ratings.html
A23: Rf | B23: =B6 -> 0.043
A24: Cost of Debt | B24: =B23+B22 -> 0.0585
